Workbook

Sheet Read Me
B2: INVOICE CHASER — SaaS Financial Model
B3: Automated invoice follow-up for French auto-entrepreneurs · 36-month monthly build
B5: HOW TO USE THIS MODEL
B6: Change one cell to re-run | C6: Assumptions!B5 is the scenario switch. Enter 1 (Conservative), 2 (Base) or 3 (Aggressive). Every sheet recalculates from it. Example: set B5 = 3 and the Dashboard repoints to the Aggressive case.
B7: Change the drivers | C7: On Assumptions, edit columns C, D and E (the three scenario columns). Column F is the LIVE column — it is a formula, do not type over it. Everything downstream reads column F only.
B8: Nothing else is an input | C8: Cohorts, P&L, Cash Flow, Unit Economics and Dashboard are 100% formula-driven. If you need to change a number, change it on Assumptions.
B10: COLOUR LEGEND
B11: Blue text | C11: Hardcoded input. Safe to edit.
B12: Yellow fill | C12: Key lever — the cells worth stress-testing first.
B13: Black text | C13: Formula. Do not overwrite.
B14: Green text | C14: Link to another sheet. Do not overwrite.
B16: SHEET MAP
B17: Assumptions | C17: All drivers, three scenarios side by side, plus a derived block (ARPU, blended churn, implied lifetime).
B18: Cohorts | C18: Acquisition funnel, then two 36x36 cohort waterfalls — one for monthly plans (constant monthly churn), one for annual plans (no churn inside the committed year, renewal decision at each 12-month anniversary).
B19: P&L | C19: Billings vs recognised revenue, cost of revenue, gross margin, opex, EBITDA.
B20: Cash Flow | C20: Cash walk plus a deferred revenue rollforward for annual prepayments, and an integrity check row.
B21: Unit Economics | C21: LTV, CAC (paid and blended), payback, LTV:CAC, and two sensitivity grids.
B22: Dashboard | C22: Headline outputs, breakeven months, funding requirement, NPV, and two charts.
B24: HOW THE ANNUAL PLAN IS MODELLED
B25: Why it matters | C25: Annual prepayment is the single biggest cash lever a low-ticket SaaS has. Ignoring it overstates the funding gap; treating cash as revenue overstates the P&L. This model separates the two.
B26: Billings | C26: An annual customer is charged 10x the monthly price upfront (2 months free) in their cohort month, and again at each anniversary if they renew.
B27: Revenue | C27: Recognised straight-line: 10/12 of the monthly price, each month, for 12 months.
B28: The difference | C28: Sits in deferred revenue on the Cash Flow sheet. Cash Flow row 22 checks that Net cash flow − EBITDA − Δdeferred = 0 in every month. It must read zero across the row.
B30: HEALTH WARNING ON THE NUMBERS
B31: These are benchmarks, not evidence | C31: Every operating assumption here is a placeholder drawn from typical low-ticket, self-serve B2B SaaS ranges. None of it is observed data for this product. The model is a decision framework, not a forecast.
B32: The three that decide the business | C32: Monthly churn, trial-to-paid conversion, and blended CPC. The Unit Economics sensitivity grids show that the verdict flips inside plausible ranges of these three — so they are what validation has to resolve first.
B33: Cheapest way to test them | C33: Churn and conversion need a landing page and ~20 customer conversations, not a spreadsheet. CPC can be read off a €200 test campaign in a week. Do that before trusting any output on the Dashboard.
B34: Not modelled | C34: VAT/TVA treatment, corporate tax, any founder opportunity cost beyond the salary line, and competitive response. Add them before this goes in front of anyone external.

Sheet Assumptions
A2: ASSUMPTIONS & SCENARIO DRIVERS
A3: Edit columns C–E only. Column F is the live selection and feeds every other sheet.
A5: Scenario switch (1 = Conservative, 2 = Base, 3 = Aggressive) | B5: 2
A6: Active scenario | B6: =INDEX(C6:E6,$B$5) -> Base | C6: Conservative | D6: Base | E6: Aggressive
A8: Driver | B8: Unit | C8: Conservative | D8: Base | E8: Aggressive | F8: LIVE | G8: Basis / how to validate
A9: PRICING & PLANS
A10: Solo plan price | B10: € / month | C10: 9 | D10: 9 | E10: 12 | F10: =INDEX(C10:E10,$B$5) -> 9 | G10: Placeholder. Anchored below what a comptable charges for the same chasing. Validate with pricing interviews.
A11: Pro plan price | B11: € / month | C11: 19 | D11: 19 | E11: 24 | F11: =INDEX(C11:E11,$B$5) -> 19 | G11: Placeholder. Pro = multi-client, custom sequences, reminders by SMS.
A12: Pro plan share of customers | B12: % of customers | C12: 0.2 | D12: 0.3 | E12: 0.35 | F12: =INDEX(C12:E12,$B$5) -> 0.3 | G12: Placeholder. Share of base on the higher tier.
A13: Annual plan share of new customers | B13: % of new | C13: 0.15 | D13: 0.2 | E13: 0.25 | F13: =INDEX(C13:E13,$B$5) -> 0.2 | G13: Key cash lever. Self-serve SaaS at this price point rarely pushes past ~25% annual without a hard discount.
A14: Annual plan — months free vs 12x monthly | B14: months | C14: 2 | D14: 2 | E14: 2 | F14: =INDEX(C14:E14,$B$5) -> 2 | G14: Standard 2-months-free annual offer, i.e. pay for 10, get 12.
A15: ACQUISITION
A16: Paid marketing spend, month 1 | B16: € / month | C16: 300 | D16: 500 | E16: 900 | F16: =INDEX(C16:E16,$B$5) -> 500 | G16: Founder-funded test budget in month 1.
A17: Paid spend growth | B17: % / month | C17: 0.06 | D17: 0.08 | E17: 0.1 | F17: =INDEX(C17:E17,$B$5) -> 0.08 | G17: Reinvestment pace. Deliberately slow — spend is capped below.
A18: Paid spend ceiling | B18: € / month | C18: 3000 | D18: 6000 | E18: 12000 | F18: =INDEX(C18:E18,$B$5) -> 6000 | G18: Ceiling. Reflects a genuinely narrow niche — French micro-entrepreneurs searching for invoice chasing. The addressable paid inventory runs out.
A19: Blended cost per click | B19: € | C19: 1.1 | D19: 0.8 | E19: 0.6 | F19: =INDEX(C19:E19,$B$5) -> 0.8 | G19: Key lever. Placeholder for French-language Google/Meta on low-competition long-tail terms. Testable for ~€200 in one week — do this first.
A20: Landing page → free trial | B20: % | C20: 0.025 | D20: 0.04 | E20: 0.055 | F20: =INDEX(C20:E20,$B$5) -> 0.04 | G20: Placeholder. Typical range for a self-serve tool with a clear single job-to-be-done.
A21: Free trial → paid | B21: % | C21: 0.15 | D21: 0.22 | E21: 0.28 | F21: =INDEX(C21:E21,$B$5) -> 0.22 | G21: Key lever. Trial-to-paid for no-credit-card self-serve trials. Drives CAC almost as hard as CPC.
A22: Organic trials, month 1 | B22: trials | C22: 10 | D22: 20 | E22: 35 | F22: =INDEX(C22:E22,$B$5) -> 20 | G22: Content/SEO and community (forums, LinkedIn, auto-entrepreneur groups). Zero marginal cost, slow to build.
A23: Organic trial growth | B23: % / month | C23: 0.08 | D23: 0.12 | E23: 0.16 | F23: =INDEX(C23:E23,$B$5) -> 0.12 | G23: Compounding content effect.
A24: Organic trial ceiling | B24: trials / month | C24: 150 | D24: 400 | E24: 800 | F24: =INDEX(C24:E24,$B$5) -> 400 | G24: Ceiling. Organic demand for this niche is finite.
A25: Referral trials per active customer | B25: / month | C25: 0.005 | D25: 0.015 | E25: 0.03 | F25: =INDEX(C25:E25,$B$5) -> 0.015 | G25: Word of mouth. Freelancers talk, but they are not a dense network.
A26: RETENTION
A27: Monthly-plan gross churn | B27: % / month | C27: 0.08 | D27: 0.06 | E27: 0.045 | F27: =INDEX(C27:E27,$B$5) -> 0.06 | G27: Single most important assumption. High by SaaS standards because the customer base itself churns — micro-entrepreneurs deregister, go salaried, or stop invoicing. This is not a product-quality number.
A28: Annual-plan renewal rate at each anniversary | B28: % | C28: 0.6 | D28: 0.7 | E28: 0.8 | F28: =INDEX(C28:E28,$B$5) -> 0.7 | G28: Applied once every 12 months. Annual customers cannot churn mid-commitment.
A29: COST OF REVENUE
A30: Infrastructure & automation per customer | B30: € / cust / month | C30: 0.45 | D30: 0.35 | E30: 0.28 | F30: =INDEX(C30:E30,$B$5) -> 0.35 | G30: n8n execution volume, storage, API calls. Falls with scale as fixed capacity is absorbed.
A31: Email & messaging per customer | B31: € / cust / month | C31: 0.15 | D31: 0.1 | E31: 0.08 | F31: =INDEX(C31:E31,$B$5) -> 0.1 | G31: Transactional email volume — each customer sends multiple reminder sequences per month.
A32: Support cost per customer | B32: € / cust / month | C32: 0.5 | D32: 0.3 | E32: 0.2 | F32: =INDEX(C32:E32,$B$5) -> 0.3 | G32: Founder time costed at a notional rate. At €9/month, support is what kills the margin — watch this line.
A33: Payment processing — % of billings | B33: % | C33: 0.015 | D33: 0.015 | E33: 0.015 | F33: =INDEX(C33:E33,$B$5) -> 0.015 | G33: Stripe standard European card rate. Verify against current Stripe pricing before relying on it.
A34: Payment processing — fee per transaction | B34: € | C34: 0.25 | D34: 0.25 | E34: 0.25 | F34: =INDEX(C34:E34,$B$5) -> 0.25 | G34: Stripe per-transaction fee. This is why annual billing helps margin, not just cash — one charge, not twelve.
A35: Fixed platform cost | B35: € / month | C35: 90 | D35: 70 | E35: 70 | F35: =INDEX(C35:E35,$B$5) -> 70 | G35: n8n cloud plan, hosting baseline, domain. Does not scale with customers.
A36: OPERATING EXPENSES
A37: Founder compensation once drawn | B37: € / month | C37: 1500 | D37: 2500 | E37: 3500 | F37: =INDEX(C37:E37,$B$5) -> 2500 | G37: Set by you. Note this is a side project — the real cost is hours, not euros, until this line switches on.
A38: First month founder is paid | B38: month # | C38: 13 | D38: 13 | E38: 10 | F38: =INDEX(C38:E38,$B$5) -> 13 | G38: Key lever. The month the business stops being free to run. Moving this earlier is the fastest way to break the cash line.
A39: Tools & software | B39: € / month | C39: 150 | D39: 120 | E39: 120 | F39: =INDEX(C39:E39,$B$5) -> 120 | G39: Stripe dashboard extras, analytics, design, hosting for the marketing site.
A40: Legal, accounting & admin | B40: € / month | C40: 120 | D40: 80 | E40: 80 | F40: =INDEX(C40:E40,$B$5) -> 80 | G40: Accountant, company admin, CGU/RGPD review. RGPD matters here — the product touches client contact data.
A41: Fixed opex inflation | B41: % / month | C41: 0.005 | D41: 0.005 | E41: 0.005 | F41: =INDEX(C41:E41,$B$5) -> 0.005 | G41: Applied to tools and admin only. ~6% annualised.
A42: FINANCING & VALUATION
A43: Opening cash (founder contribution) | B43: € | C43: 5000 | D43: 5000 | E43: 5000 | F43: =INDEX(C43:E43,$B$5) -> 5000 | G43: Set by you. The model tells you whether this is enough.
...

Sheet Cohorts
A2: COHORT ENGINE
A3: Acquisition funnel, then customer waterfalls by cohort. Monthly plans churn every month; annual plans are locked for 12 and face a renewal decision at each anniversary.
A5: Month index | B5: # | C5: 1 | D5: 2 | E5: 3 | F5: 4 | G5: 5 | H5: 6 | I5: 7 | J5: 8 | K5: 9 | L5: 10 | M5: 11 | N5: 12 | O5: 13 | P5: 14 | Q5: 15 | R5: 16 | S5: 17 | T5: 18 | U5: 19 | V5: 20 | W5: 21 | X5: 22 | Y5: 23 | Z5: 24 | AA5: 25 | AB5: 26 | AC5: 27 | AD5: 28 | AE5: 29 | AF5: 30 | AG5: 31 | AH5: 32 | AI5: 33 | AJ5: 34 | AK5: 35 | AL5: 36
A7: ACQUISITION FUNNEL
A8: Paid marketing spend | B8: € | C8: =MIN(Assumptions!$F$18,Assumptions!$F$16*(1+Assumptions!$F$17)^(C5-1)) -> 500 | D8: =MIN(Assumptions!$F$18,Assumptions!$F$16*(1+Assumptions!$F$17)^(D5-1)) -> 540 | E8: =MIN(Assumptions!$F$18,Assumptions!$F$16*(1+Assumptions!$F$17)^(E5-1)) -> 583.2 | F8: =MIN(Assumptions!$F$18,Assumptions!$F$16*(1+Assumptions!$F$17)^(F5-1)) -> 629.856 | G8: =MIN(Assumptions!$F$18,Assumptions!$F$16*(1+Assumptions!$F$17)^(G5-1)) -> 680.24448 | H8: =MIN(Assumptions!$F$18,Assumptions!$F$16*(1+Assumptions!$F$17)^(H5-1)) -> 734.66404 | I8: =MIN(Assumptions!$F$18,Assumptions!$F$16*(1+Assumptions!$F$17)^(I5-1)) -> 793.43716 | J8: =MIN(Assumptions!$F$18,Assumptions!$F$16*(1+Assumptions!$F$17)^(J5-1)) -> 856.91213 | ... AL8: =MIN(Assumptions!$F$18,Assumptions!$F$16*(1+Assumptions!$F$17)^(AL5-1)) -> 6000
A9: Paid visitors | B9: # | C9: =IF(Assumptions!$F$19=0,0,C8/Assumptions!$F$19) -> 625 | D9: =IF(Assumptions!$F$19=0,0,D8/Assumptions!$F$19) -> 675 | E9: =IF(Assumptions!$F$19=0,0,E8/Assumptions!$F$19) -> 729 | F9: =IF(Assumptions!$F$19=0,0,F8/Assumptions!$F$19) -> 787.32 | G9: =IF(Assumptions!$F$19=0,0,G8/Assumptions!$F$19) -> 850.3056 | H9: =IF(Assumptions!$F$19=0,0,H8/Assumptions!$F$19) -> 918.33005 | I9: =IF(Assumptions!$F$19=0,0,I8/Assumptions!$F$19) -> 991.79645 | J9: =IF(Assumptions!$F$19=0,0,J8/Assumptions!$F$19) -> 1071.1402 | ... AL9: =IF(Assumptions!$F$19=0,0,AL8/Assumptions!$F$19) -> 7500
A10: Paid trials | B10: # | C10: =C9*Assumptions!$F$20 -> 25 | D10: =D9*Assumptions!$F$20 -> 27 | E10: =E9*Assumptions!$F$20 -> 29.16 | F10: =F9*Assumptions!$F$20 -> 31.4928 | G10: =G9*Assumptions!$F$20 -> 34.012224 | H10: =H9*Assumptions!$F$20 -> 36.733202 | I10: =I9*Assumptions!$F$20 -> 39.671858 | J10: =J9*Assumptions!$F$20 -> 42.845607 | ... AL10: =AL9*Assumptions!$F$20 -> 300
A11: Organic trials | B11: # | C11: =MIN(Assumptions!$F$24,Assumptions!$F$22*(1+Assumptions!$F$23)^(C5-1)) -> 20 | D11: =MIN(Assumptions!$F$24,Assumptions!$F$22*(1+Assumptions!$F$23)^(D5-1)) -> 22.4 | E11: =MIN(Assumptions!$F$24,Assumptions!$F$22*(1+Assumptions!$F$23)^(E5-1)) -> 25.088 | F11: =MIN(Assumptions!$F$24,Assumptions!$F$22*(1+Assumptions!$F$23)^(F5-1)) -> 28.09856 | G11: =MIN(Assumptions!$F$24,Assumptions!$F$22*(1+Assumptions!$F$23)^(G5-1)) -> 31.470387 | H11: =MIN(Assumptions!$F$24,Assumptions!$F$22*(1+Assumptions!$F$23)^(H5-1)) -> 35.246834 | I11: =MIN(Assumptions!$F$24,Assumptions!$F$22*(1+Assumptions!$F$23)^(I5-1)) -> 39.476454 | J11: =MIN(Assumptions!$F$24,Assumptions!$F$22*(1+Assumptions!$F$23)^(J5-1)) -> 44.213628 | ... AL11: =MIN(Assumptions!$F$24,Assumptions!$F$22*(1+Assumptions!$F$23)^(AL5-1)) -> 400
A12: Referral trials | B12: # | C12: =C22*Assumptions!$F$25 -> 0 | D12: =D22*Assumptions!$F$25 -> 0.1485 | E12: =E22*Assumptions!$F$25 -> 0.30488205 | F12: =F22*Assumptions!$F$25 -> 0.47035776 | G12: =G22*Assumptions!$F$25 -> 0.64624438 | H12: =H22*Assumptions!$F$25 -> 0.8339778 | I12: =I22*Assumptions!$F$25 -> 1.0351269 | J12: =J22*Assumptions!$F$25 -> 1.2514097 | ... AL12: =AL22*Assumptions!$F$25 -> 24.334608
A13: Total trials | B13: # | C13: =SUM(C10:C12) -> 45 | D13: =SUM(D10:D12) -> 49.5485 | E13: =SUM(E10:E12) -> 54.552882 | F13: =SUM(F10:F12) -> 60.061718 | G13: =SUM(G10:G12) -> 66.128856 | H13: =SUM(H10:H12) -> 72.814013 | I13: =SUM(I10:I12) -> 80.183439 | J13: =SUM(J10:J12) -> 88.310645 | ... AL13: =SUM(AL10:AL12) -> 724.33461
A14: New paying customers | B14: # | C14: =C13*Assumptions!$F$21 -> 9.9 | D14: =D13*Assumptions!$F$21 -> 10.90067 | E14: =E13*Assumptions!$F$21 -> 12.001634 | F14: =F13*Assumptions!$F$21 -> 13.213578 | G14: =G13*Assumptions!$F$21 -> 14.548348 | H14: =H13*Assumptions!$F$21 -> 16.019083 | I14: =I13*Assumptions!$F$21 -> 17.640357 | J14: =J13*Assumptions!$F$21 -> 19.428342 | ... AL14: =AL13*Assumptions!$F$21 -> 159.35361
A15: — new on monthly plan | B15: # | C15: =C14*(1-Assumptions!$F$13) -> 7.92 | D15: =D14*(1-Assumptions!$F$13) -> 8.720536 | E15: =E14*(1-Assumptions!$F$13) -> 9.6013072 | F15: =F14*(1-Assumptions!$F$13) -> 10.570862 | G15: =G14*(1-Assumptions!$F$13) -> 11.638679 | H15: =H14*(1-Assumptions!$F$13) -> 12.815266 | I15: =I14*(1-Assumptions!$F$13) -> 14.112285 | J15: =J14*(1-Assumptions!$F$13) -> 15.542673 | ... AL15: =AL14*(1-Assumptions!$F$13) -> 127.48289
A16: — new on annual plan | B16: # | C16: =C14*Assumptions!$F$13 -> 1.98 | D16: =D14*Assumptions!$F$13 -> 2.180134 | E16: =E14*Assumptions!$F$13 -> 2.4003268 | F16: =F14*Assumptions!$F$13 -> 2.6427156 | G16: =G14*Assumptions!$F$13 -> 2.9096696 | H16: =H14*Assumptions!$F$13 -> 3.2038166 | I16: =I14*Assumptions!$F$13 -> 3.5280713 | J16: =J14*Assumptions!$F$13 -> 3.8856684 | ... AL16: =AL14*Assumptions!$F$13 -> 31.870723
A18: ACTIVE CUSTOMERS
A19: Monthly-plan customers (closing) | B19: # | C19: =SUM(C27:C62) -> 7.92 | D19: =SUM(D27:D62) -> 16.165336 | E19: =SUM(E27:E62) -> 24.796723 | F19: =SUM(F27:F62) -> 33.879782 | G19: =SUM(G27:G62) -> 43.485674 | H19: =SUM(H27:H62) -> 53.6918 | I19: =SUM(I27:I62) -> 64.582577 | J19: =SUM(J27:J62) -> 76.250296 | ... AL19: =SUM(AL27:AL62) -> 1246.6676
A20: Annual-plan customers (closing) | B20: # | C20: =SUM(C66:C101) -> 1.98 | D20: =SUM(D66:D101) -> 4.160134 | E20: =SUM(E66:E101) -> 6.5604608 | F20: =SUM(F66:F101) -> 9.2031764 | G20: =SUM(G66:G101) -> 12.112846 | H20: =SUM(H66:H101) -> 15.316663 | I20: =SUM(I66:I101) -> 18.844734 | J20: =SUM(J66:J101) -> 22.730402 | ... AL20: =SUM(AL66:AL101) -> 456.71958
A21: Total active customers (closing) | B21: # | C21: =C19+C20 -> 9.9 | D21: =D19+D20 -> 20.32547 | E21: =E19+E20 -> 31.357184 | F21: =F19+F20 -> 43.082958 | G21: =G19+G20 -> 55.59852 | H21: =H19+H20 -> 69.008462 | I21: =I19+I20 -> 83.427311 | J21: =J19+J20 -> 98.980698 | ... AL21: =AL19+AL20 -> 1703.3872
A22: Total active customers (opening) | B22: # | C22: =0 -> 0 | D22: =C21 -> 9.9 | E22: =D21 -> 20.32547 | F22: =E21 -> 31.357184 | G22: =F21 -> 43.082958 | H22: =G21 -> 55.59852 | I22: =H21 -> 69.008462 | J22: =I21 -> 83.427311 | K22: =J21 -> 98.980698 | ... AL22: =AK21 -> 1622.3072
A23: Annual plans billed this month | B23: # | C23: =C16 -> 1.98 | D23: =D16 -> 2.180134 | E23: =E16 -> 2.4003268 | F23: =F16 -> 2.6427156 | G23: =G16 -> 2.9096696 | H23: =H16 -> 3.2038166 | I23: =I16 -> 3.5280713 | J23: =J16 -> 3.8856684 | ... N23: =N16 -> 5.7275006 | O23: =O16+O66 -> 7.7002881 | P23: =P16+P67 -> 8.4885795 | Q23: =Q16+Q68 -> 9.3594247 | R23: =R16+R69 -> 10.321823 | S23: =S16+S70 -> 11.385777 | T23: =T16+T71 -> 12.56241 | U23: =U16+U72 -> 13.864089 | V23: =V16+V73 -> 15.304572 | W23: =W16+W74 -> 16.899167 | X23: =X16+X75 -> 18.664904 | Y23: =Y16+Y76 -> 20.620743 | Z23: =Z16+Z77 -> 22.787788 | AA23: =AA16+AA78+AA66 -> 26.159735 | AB23: =AB16+AB79+AB67 -> 28.919869 | AC23: =AC16+AC80+AC68 -> 31.979793 | AD23: =AD16+AD81+AD69 -> 34.207122 | AE23: =AE16+AE82+AE70 -> 35.715224 | AF23: =AF16+AF83+AF71 -> 37.358068 | AG23: =AG16+AG84+AG72 -> 39.149012 | AH23: =AH16+AH85+AH73 -> 41.102749 | AI23: =AI16+AI86+AI74 -> 43.235448 | AJ23: =AJ16+AJ87+AJ75 -> 44.821254 | AK23: =AK16+AK88+AK76 -> 46.249135 | AL23: =AL16+AL89+AL77 -> 47.822174
A24: New annual sign-ups plus the cohorts hitting their 12- and 24-month anniversary (post-renewal count).
A25: COHORT WATERFALL — MONTHLY PLAN (active customers)
A26: Cohort ↓ / Month → | B26: # | C26: 1 | D26: 2 | E26: 3 | F26: 4 | G26: 5 | H26: 6 | I26: 7 | J26: 8 | K26: 9 | L26: 10 | M26: 11 | N26: 12 | O26: 13 | P26: 14 | Q26: 15 | R26: 16 | S26: 17 | T26: 18 | U26: 19 | V26: 20 | W26: 21 | X26: 22 | Y26: 23 | Z26: 24 | AA26: 25 | AB26: 26 | AC26: 27 | AD26: 28 | AE26: 29 | AF26: 30 | AG26: 31 | AH26: 32 | AI26: 33 | AJ26: 34 | AK26: 35 | AL26: 36
A27: Cohort M1 | B27: # | C27: =C15 -> 7.92 | D27: =C27*(1-Assumptions!$F$27) -> 7.4448 | E27: =D27*(1-Assumptions!$F$27) -> 6.998112 | F27: =E27*(1-Assumptions!$F$27) -> 6.5782253 | G27: =F27*(1-Assumptions!$F$27) -> 6.1835318 | H27: =G27*(1-Assumptions!$F$27) -> 5.8125199 | I27: =H27*(1-Assumptions!$F$27) -> 5.4637687 | J27: =I27*(1-Assumptions!$F$27) -> 5.1359425 | K27: =J27*(1-Assumptions!$F$27) -> 4.827786 | ... AL27: =AK27*(1-Assumptions!$F$27) -> 0.90823881
A28: Cohort M2 | B28: # | C28: 0 | D28: =D15 -> 8.720536 | E28: =D28*(1-Assumptions!$F$27) -> 8.1973038 | F28: =E28*(1-Assumptions!$F$27) -> 7.7054656 | G28: =F28*(1-Assumptions!$F$27) -> 7.2431377 | H28: =G28*(1-Assumptions!$F$27) -> 6.8085494 | I28: =H28*(1-Assumptions!$F$27) -> 6.4000364 | J28: =I28*(1-Assumptions!$F$27) -> 6.0160343 | K28: =J28*(1-Assumptions!$F$27) -> 5.6550722 | L28: =K28*(1-Assumptions!$F$27) -> 5.3157679 | ... AL28: =AK28*(1-Assumptions!$F$27) -> 1.063874
A29: Cohort M3 | B29: # | C29: 0 | D29: 0 | E29: =E15 -> 9.6013072 | F29: =E29*(1-Assumptions!$F$27) -> 9.0252288 | G29: =F29*(1-Assumptions!$F$27) -> 8.4837151 | H29: =G29*(1-Assumptions!$F$27) -> 7.9746922 | I29: =H29*(1-Assumptions!$F$27) -> 7.4962106 | J29: =I29*(1-Assumptions!$F$27) -> 7.046438 | K29: =J29*(1-Assumptions!$F$27) -> 6.6236517 | L29: =K29*(1-Assumptions!$F$27) -> 6.2262326 | M29: =L29*(1-Assumptions!$F$27) -> 5.8526587 | ... AL29: =AK29*(1-Assumptions!$F$27) -> 1.2460904
A30: Cohort M4 | B30: # | C30: 0 | D30: 0 | E30: 0 | F30: =F15 -> 10.570862 | G30: =F30*(1-Assumptions!$F$27) -> 9.9366106 | H30: =G30*(1-Assumptions!$F$27) -> 9.340414 | I30: =H30*(1-Assumptions!$F$27) -> 8.7799891 | J30: =I30*(1-Assumptions!$F$27) -> 8.2531898 | K30: =J30*(1-Assumptions!$F$27) -> 7.7579984 | L30: =K30*(1-Assumptions!$F$27) -> 7.2925185 | M30: =L30*(1-Assumptions!$F$27) -> 6.8549674 | N30: =M30*(1-Assumptions!$F$27) -> 6.4436693 | ... AL30: =AK30*(1-Assumptions!$F$27) -> 1.459492
A31: Cohort M5 | B31: # | C31: 0 | D31: 0 | E31: 0 | F31: 0 | G31: =G15 -> 11.638679 | H31: =G31*(1-Assumptions!$F$27) -> 10.940358 | I31: =H31*(1-Assumptions!$F$27) -> 10.283936 | J31: =I31*(1-Assumptions!$F$27) -> 9.6669002 | K31: =J31*(1-Assumptions!$F$27) -> 9.0868862 | L31: =K31*(1-Assumptions!$F$27) -> 8.541673 | M31: =L31*(1-Assumptions!$F$27) -> 8.0291726 | N31: =M31*(1-Assumptions!$F$27) -> 7.5474223 | O31: =N31*(1-Assumptions!$F$27) -> 7.0945769 | ... AL31: =AK31*(1-Assumptions!$F$27) -> 1.7094923
A32: Cohort M6 | B32: # | C32: 0 | D32: 0 | E32: 0 | F32: 0 | G32: 0 | H32: =H15 -> 12.815266 | I32: =H32*(1-Assumptions!$F$27) -> 12.04635 | J32: =I32*(1-Assumptions!$F$27) -> 11.323569 | K32: =J32*(1-Assumptions!$F$27) -> 10.644155 | L32: =K32*(1-Assumptions!$F$27) -> 10.005506 | M32: =L32*(1-Assumptions!$F$27) -> 9.4051755 | N32: =M32*(1-Assumptions!$F$27) -> 8.840865 | O32: =N32*(1-Assumptions!$F$27) -> 8.3104131 | P32: =O32*(1-Assumptions!$F$27) -> 7.8117883 | ... AL32: =AK32*(1-Assumptions!$F$27) -> 2.0024572
A33: Cohort M7 | B33: # | C33: 0 | D33: 0 | E33: 0 | F33: 0 | G33: 0 | H33: 0 | I33: =I15 -> 14.112285 | J33: =I33*(1-Assumptions!$F$27) -> 13.265548 | K33: =J33*(1-Assumptions!$F$27) -> 12.469615 | L33: =K33*(1-Assumptions!$F$27) -> 11.721438 | M33: =L33*(1-Assumptions!$F$27) -> 11.018152 | N33: =M33*(1-Assumptions!$F$27) -> 10.357063 | O33: =N33*(1-Assumptions!$F$27) -> 9.7356391 | P33: =O33*(1-Assumptions!$F$27) -> 9.1515008 | Q33: =P33*(1-Assumptions!$F$27) -> 8.6024107 | ... AL33: =AK33*(1-Assumptions!$F$27) -> 2.3458763
A34: Cohort M8 | B34: # | C34: 0 | D34: 0 | E34: 0 | F34: 0 | G34: 0 | H34: 0 | I34: 0 | J34: =J15 -> 15.542673 | K34: =J34*(1-Assumptions!$F$27) -> 14.610113 | L34: =K34*(1-Assumptions!$F$27) -> 13.733506 | M34: =L34*(1-Assumptions!$F$27) -> 12.909496 | N34: =M34*(1-Assumptions!$F$27) -> 12.134926 | O34: =N34*(1-Assumptions!$F$27) -> 11.406831 | P34: =O34*(1-Assumptions!$F$27) -> 10.722421 | Q34: =P34*(1-Assumptions!$F$27) -> 10.079075 | R34: =Q34*(1-Assumptions!$F$27) -> 9.4743309 | ... AL34: =AK34*(1-Assumptions!$F$27) -> 2.7485625
A35: Cohort M9 | B35: # | C35: 0 | D35: 0 | E35: 0 | F35: 0 | G35: 0 | H35: 0 | I35: 0 | J35: 0 | K35: =K15 -> 17.120792 | L35: =K35*(1-Assumptions!$F$27) -> 16.093545 | M35: =L35*(1-Assumptions!$F$27) -> 15.127932 | N35: =M35*(1-Assumptions!$F$27) -> 14.220256 | O35: =N35*(1-Assumptions!$F$27) -> 13.367041 | P35: =O35*(1-Assumptions!$F$27) -> 12.565018 | Q35: =P35*(1-Assumptions!$F$27) -> 11.811117 | R35: =Q35*(1-Assumptions!$F$27) -> 11.10245 | S35: =R35*(1-Assumptions!$F$27) -> 10.436303 | ... AL35: =AK35*(1-Assumptions!$F$27) -> 3.2208901
A36: Cohort M10 | B36: # | C36: 0 | D36: 0 | E36: 0 | F36: 0 | G36: 0 | H36: 0 | I36: 0 | J36: 0 | K36: 0 | L36: =L15 -> 18.862587 | M36: =L36*(1-Assumptions!$F$27) -> 17.730832 | N36: =M36*(1-Assumptions!$F$27) -> 16.666982 | O36: =N36*(1-Assumptions!$F$27) -> 15.666963 | P36: =O36*(1-Assumptions!$F$27) -> 14.726945 | Q36: =P36*(1-Assumptions!$F$27) -> 13.843329 | R36: =Q36*(1-Assumptions!$F$27) -> 13.012729 | S36: =R36*(1-Assumptions!$F$27) -> 12.231965 | T36: =S36*(1-Assumptions!$F$27) -> 11.498047 | ... AL36: =AK36*(1-Assumptions!$F$27) -> 3.7750739
A37: Cohort M11 | B37: # | C37: 0 | D37: 0 | E37: 0 | F37: 0 | G37: 0 | H37: 0 | I37: 0 | J37: 0 | K37: 0 | L37: 0 | M37: =M15 -> 20.785767 | N37: =M37*(1-Assumptions!$F$27) -> 19.538621 | O37: =N37*(1-Assumptions!$F$27) -> 18.366303 | P37: =O37*(1-Assumptions!$F$27) -> 17.264325 | Q37: =P37*(1-Assumptions!$F$27) -> 16.228466 | R37: =Q37*(1-Assumptions!$F$27) -> 15.254758 | S37: =R37*(1-Assumptions!$F$27) -> 14.339472 | T37: =S37*(1-Assumptions!$F$27) -> 13.479104 | U37: =T37*(1-Assumptions!$F$27) -> 12.670358 | ... AL37: =AK37*(1-Assumptions!$F$27) -> 4.4255004
A38: Cohort M12 | B38: # | C38: 0 | D38: 0 | E38: 0 | F38: 0 | G38: 0 | H38: 0 | I38: 0 | J38: 0 | K38: 0 | L38: 0 | M38: 0 | N38: =N15 -> 22.910002 | O38: =N38*(1-Assumptions!$F$27) -> 21.535402 | P38: =O38*(1-Assumptions!$F$27) -> 20.243278 | Q38: =P38*(1-Assumptions!$F$27) -> 19.028681 | R38: =Q38*(1-Assumptions!$F$27) -> 17.88696 | S38: =R38*(1-Assumptions!$F$27) -> 16.813743 | T38: =S38*(1-Assumptions!$F$27) -> 15.804918 | U38: =T38*(1-Assumptions!$F$27) -> 14.856623 | V38: =U38*(1-Assumptions!$F$27) -> 13.965226 | ... AL38: =AK38*(1-Assumptions!$F$27) -> 5.1891189
A39: Cohort M13 | B39: # | C39: 0 | D39: 0 | E39: 0 | F39: 0 | G39: 0 | H39: 0 | I39: 0 | J39: 0 | K39: 0 | L39: 0 | M39: 0 | N39: 0 | O39: =O15 -> 25.257153 | P39: =O39*(1-Assumptions!$F$27) -> 23.741723 | Q39: =P39*(1-Assumptions!$F$27) -> 22.31722 | R39: =Q39*(1-Assumptions!$F$27) -> 20.978187 | S39: =R39*(1-Assumptions!$F$27) -> 19.719496 | T39: =S39*(1-Assumptions!$F$27) -> 18.536326 | U39: =T39*(1-Assumptions!$F$27) -> 17.424146 | V39: =U39*(1-Assumptions!$F$27) -> 16.378698 | W39: =V39*(1-Assumptions!$F$27) -> 15.395976 | ... AL39: =AK39*(1-Assumptions!$F$27) -> 6.0859029
A40: Cohort M14 | B40: # | C40: 0 | D40: 0 | E40: 0 | F40: 0 | G40: 0 | H40: 0 | I40: 0 | J40: 0 | K40: 0 | L40: 0 | M40: 0 | N40: 0 | O40: 0 | P40: =P15 -> 27.849943 | Q40: =P40*(1-Assumptions!$F$27) -> 26.178946 | R40: =Q40*(1-Assumptions!$F$27) -> 24.608209 | S40: =R40*(1-Assumptions!$F$27) -> 23.131717 | T40: =S40*(1-Assumptions!$F$27) -> 21.743814 | U40: =T40*(1-Assumptions!$F$27) -> 20.439185 | V40: =U40*(1-Assumptions!$F$27) -> 19.212834 | W40: =V40*(1-Assumptions!$F$27) -> 18.060064 | X40: =W40*(1-Assumptions!$F$27) -> 16.97646 | ... AL40: =AK40*(1-Assumptions!$F$27) -> 7.1389952
A41: Cohort M15 | B41: # | C41: 0 | D41: 0 | E41: 0 | F41: 0 | G41: 0 | H41: 0 | I41: 0 | J41: 0 | K41: 0 | L41: 0 | M41: 0 | N41: 0 | O41: 0 | P41: 0 | Q41: =Q15 -> 30.716784 | R41: =Q41*(1-Assumptions!$F$27) -> 28.873777 | S41: =R41*(1-Assumptions!$F$27) -> 27.14135 | T41: =S41*(1-Assumptions!$F$27) -> 25.512869 | U41: =T41*(1-Assumptions!$F$27) -> 23.982097 | V41: =U41*(1-Assumptions!$F$27) -> 22.543171 | W41: =V41*(1-Assumptions!$F$27) -> 21.190581 | X41: =W41*(1-Assumptions!$F$27) -> 19.919146 | Y41: =X41*(1-Assumptions!$F$27) -> 18.723997 | ... AL41: =AK41*(1-Assumptions!$F$27) -> 8.3764628
A42: Cohort M16 | B42: # | C42: 0 | D42: 0 | E42: 0 | F42: 0 | G42: 0 | H42: 0 | I42: 0 | J42: 0 | K42: 0 | L42: 0 | M42: 0 | N42: 0 | O42: 0 | P42: 0 | Q42: 0 | R42: =R15 -> 33.887688 | S42: =R42*(1-Assumptions!$F$27) -> 31.854427 | T42: =S42*(1-Assumptions!$F$27) -> 29.943161 | U42: =T42*(1-Assumptions!$F$27) -> 28.146571 | V42: =U42*(1-Assumptions!$F$27) -> 26.457777 | W42: =V42*(1-Assumptions!$F$27) -> 24.87031 | X42: =W42*(1-Assumptions!$F$27) -> 23.378092 | Y42: =X42*(1-Assumptions!$F$27) -> 21.975406 | Z42: =Y42*(1-Assumptions!$F$27) -> 20.656882 | ... AL42: =AK42*(1-Assumptions!$F$27) -> 9.8310297
A43: Cohort M17 | B43: # | C43: 0 | D43: 0 | E43: 0 | F43: 0 | G43: 0 | H43: 0 | I43: 0 | J43: 0 | K43: 0 | L43: 0 | M43: 0 | N43: 0 | O43: 0 | P43: 0 | Q43: 0 | R43: 0 | S43: =S15 -> 37.396034 | T43: =S43*(1-Assumptions!$F$27) -> 35.152272 | U43: =T43*(1-Assumptions!$F$27) -> 33.043135 | V43: =U43*(1-Assumptions!$F$27) -> 31.060547 | W43: =V43*(1-Assumptions!$F$27) -> 29.196914 | X43: =W43*(1-Assumptions!$F$27) -> 27.4451 | Y43: =X43*(1-Assumptions!$F$27) -> 25.798394 | Z43: =Y43*(1-Assumptions!$F$27) -> 24.25049 | AA43: =Z43*(1-Assumptions!$F$27) -> 22.795461 | ... AL43: =AK43*(1-Assumptions!$F$27) -> 11.541301
A44: Cohort M18 | B44: # | C44: 0 | D44: 0 | E44: 0 | F44: 0 | G44: 0 | H44: 0 | I44: 0 | J44: 0 | K44: 0 | L44: 0 | M44: 0 | N44: 0 | O44: 0 | P44: 0 | Q44: 0 | R44: 0 | S44: 0 | T44: =T15 -> 41.278952 | U44: =T44*(1-Assumptions!$F$27) -> 38.802215 | V44: =U44*(1-Assumptions!$F$27) -> 36.474082 | W44: =V44*(1-Assumptions!$F$27) -> 34.285637 | X44: =W44*(1-Assumptions!$F$27) -> 32.228499 | Y44: =X44*(1-Assumptions!$F$27) -> 30.294789 | Z44: =Y44*(1-Assumptions!$F$27) -> 28.477102 | AA44: =Z44*(1-Assumptions!$F$27) -> 26.768476 | AB44: =AA44*(1-Assumptions!$F$27) -> 25.162367 | ... AL44: =AK44*(1-Assumptions!$F$27) -> 13.552831
...

Sheet P&L
A2: PROFIT & LOSS
A3: Billings are cash charged. Revenue is recognised. They differ by the annual prepayment — the gap is tracked on Cash Flow.
A5: Month index | B5: # | C5: 1 | D5: 2 | E5: 3 | F5: 4 | G5: 5 | H5: 6 | I5: 7 | J5: 8 | K5: 9 | L5: 10 | M5: 11 | N5: 12 | O5: 13 | P5: 14 | Q5: 15 | R5: 16 | S5: 17 | T5: 18 | U5: 19 | V5: 20 | W5: 21 | X5: 22 | Y5: 23 | Z5: 24 | AA5: 25 | AB5: 26 | AC5: 27 | AD5: 28 | AE5: 29 | AF5: 30 | AG5: 31 | AH5: 32 | AI5: 33 | AJ5: 34 | AK5: 35 | AL5: 36
A7: BILLINGS (cash charged to the customer)
A8: Monthly-plan customers billed | B8: # | C8: =Cohorts!C19 -> 7.92 | D8: =Cohorts!D19 -> 16.165336 | E8: =Cohorts!E19 -> 24.796723 | F8: =Cohorts!F19 -> 33.879782 | G8: =Cohorts!G19 -> 43.485674 | H8: =Cohorts!H19 -> 53.6918 | I8: =Cohorts!I19 -> 64.582577 | J8: =Cohorts!J19 -> 76.250296 | ... AL8: =Cohorts!AL19 -> 1246.6676
A9: Annual plans billed | B9: # | C9: =Cohorts!C23 -> 1.98 | D9: =Cohorts!D23 -> 2.180134 | E9: =Cohorts!E23 -> 2.4003268 | F9: =Cohorts!F23 -> 2.6427156 | G9: =Cohorts!G23 -> 2.9096696 | H9: =Cohorts!H23 -> 3.2038166 | I9: =Cohorts!I23 -> 3.5280713 | J9: =Cohorts!J23 -> 3.8856684 | ... AL9: =Cohorts!AL23 -> 47.822174
A10: Monthly-plan billings | B10: € | C10: =C8*Assumptions!$F$46 -> 95.04 | D10: =D8*Assumptions!$F$46 -> 193.98403 | E10: =E8*Assumptions!$F$46 -> 297.56068 | F10: =F8*Assumptions!$F$46 -> 406.55738 | G10: =G8*Assumptions!$F$46 -> 521.82808 | H10: =H8*Assumptions!$F$46 -> 644.3016 | I10: =I8*Assumptions!$F$46 -> 774.99092 | J10: =J8*Assumptions!$F$46 -> 915.00355 | ... AL10: =AL8*Assumptions!$F$46 -> 14960.011
A11: Annual-plan billings | B11: € | C11: =C9*Assumptions!$F$49 -> 237.6 | D11: =D9*Assumptions!$F$49 -> 261.61608 | E11: =E9*Assumptions!$F$49 -> 288.03922 | F11: =F9*Assumptions!$F$49 -> 317.12587 | G11: =G9*Assumptions!$F$49 -> 349.16036 | H11: =H9*Assumptions!$F$49 -> 384.45799 | I11: =I9*Assumptions!$F$49 -> 423.36856 | J11: =J9*Assumptions!$F$49 -> 466.2802 | ... AL11: =AL9*Assumptions!$F$49 -> 5738.6609
A12: Total billings | B12: € | C12: =C10+C11 -> 332.64 | D12: =D10+D11 -> 455.60011 | E12: =E10+E11 -> 585.59989 | F12: =F10+F11 -> 723.68325 | G12: =G10+G11 -> 870.98844 | H12: =H10+H11 -> 1028.7596 | I12: =I10+I11 -> 1198.3595 | J12: =J10+J11 -> 1381.2838 | ... AL12: =AL10+AL11 -> 20698.672
A13: Card transactions | B13: # | C13: =C8+C9 -> 9.9 | D13: =D8+D9 -> 18.34547 | E13: =E8+E9 -> 27.19705 | F13: =F8+F9 -> 36.522498 | G13: =G8+G9 -> 46.395343 | H13: =H8+H9 -> 56.895616 | I13: =I8+I9 -> 68.110648 | J13: =J8+J9 -> 80.135964 | ... AL13: =AL8+AL9 -> 1294.4898
A15: REVENUE (recognised)
A16: Monthly-plan subscription revenue | B16: € | C16: =Cohorts!C19*Assumptions!$F$46 -> 95.04 | D16: =Cohorts!D19*Assumptions!$F$46 -> 193.98403 | E16: =Cohorts!E19*Assumptions!$F$46 -> 297.56068 | F16: =Cohorts!F19*Assumptions!$F$46 -> 406.55738 | G16: =Cohorts!G19*Assumptions!$F$46 -> 521.82808 | H16: =Cohorts!H19*Assumptions!$F$46 -> 644.3016 | I16: =Cohorts!I19*Assumptions!$F$46 -> 774.99092 | J16: =Cohorts!J19*Assumptions!$F$46 -> 915.00355 | ... AL16: =Cohorts!AL19*Assumptions!$F$46 -> 14960.011
A17: Annual-plan subscription revenue | B17: € | C17: =Cohorts!C20*Assumptions!$F$47 -> 19.8 | D17: =Cohorts!D20*Assumptions!$F$47 -> 41.60134 | E17: =Cohorts!E20*Assumptions!$F$47 -> 65.604608 | F17: =Cohorts!F20*Assumptions!$F$47 -> 92.031764 | G17: =Cohorts!G20*Assumptions!$F$47 -> 121.12846 | H17: =Cohorts!H20*Assumptions!$F$47 -> 153.16663 | I17: =Cohorts!I20*Assumptions!$F$47 -> 188.44734 | J17: =Cohorts!J20*Assumptions!$F$47 -> 227.30402 | ... AL17: =Cohorts!AL20*Assumptions!$F$47 -> 4567.1958
A18: Total revenue (= MRR) | B18: € | C18: =C16+C17 -> 114.84 | D18: =D16+D17 -> 235.58537 | E18: =E16+E17 -> 363.16529 | F18: =F16+F17 -> 498.58915 | G18: =G16+G17 -> 642.95654 | H18: =H16+H17 -> 797.46822 | I18: =I16+I17 -> 963.43826 | J18: =J16+J17 -> 1142.3076 | ... AL18: =AL16+AL17 -> 19527.207
A19: ARR (run-rate) | B19: € | C19: =C18*12 -> 1378.08 | D19: =D18*12 -> 2827.0245 | E19: =E18*12 -> 4357.9834 | F19: =F18*12 -> 5983.0698 | G19: =G18*12 -> 7715.4785 | H19: =H18*12 -> 9569.6187 | I19: =I18*12 -> 11561.259 | J19: =J18*12 -> 13707.691 | ... AL19: =AL18*12 -> 234326.48
A20: Revenue growth MoM | B20: % | C20: =0 -> 0 | D20: =IF(C18=0,0,D18/C18-1) -> 1.0514226 | E20: =IF(D18=0,0,E18/D18-1) -> 0.54154429 | F20: =IF(E18=0,0,F18/E18-1) -> 0.3728987 | G20: =IF(F18=0,0,G18/F18-1) -> 0.28955182 | H20: =IF(G18=0,0,H18/G18-1) -> 0.24031434 | I20: =IF(H18=0,0,I18/H18-1) -> 0.2081212 | J20: =IF(I18=0,0,J18/I18-1) -> 0.18565726 | K20: =IF(J18=0,0,K18/J18-1) -> 0.16926376 | ... AL20: =IF(AK18=0,0,AL18/AK18-1) -> 0.049606269
A22: COST OF REVENUE
A23: Infrastructure & automation | B23: € | C23: =Cohorts!C21*Assumptions!$F$30 -> 3.465 | D23: =Cohorts!D21*Assumptions!$F$30 -> 7.1139145 | E23: =Cohorts!E21*Assumptions!$F$30 -> 10.975014 | F23: =Cohorts!F21*Assumptions!$F$30 -> 15.079035 | G23: =Cohorts!G21*Assumptions!$F$30 -> 19.459482 | H23: =Cohorts!H21*Assumptions!$F$30 -> 24.152962 | I23: =Cohorts!I21*Assumptions!$F$30 -> 29.199559 | J23: =Cohorts!J21*Assumptions!$F$30 -> 34.643244 | ... AL23: =Cohorts!AL21*Assumptions!$F$30 -> 596.18551
A24: Email & messaging | B24: € | C24: =Cohorts!C21*Assumptions!$F$31 -> 0.99 | D24: =Cohorts!D21*Assumptions!$F$31 -> 2.032547 | E24: =Cohorts!E21*Assumptions!$F$31 -> 3.1357184 | F24: =Cohorts!F21*Assumptions!$F$31 -> 4.3082958 | G24: =Cohorts!G21*Assumptions!$F$31 -> 5.559852 | H24: =Cohorts!H21*Assumptions!$F$31 -> 6.9008462 | I24: =Cohorts!I21*Assumptions!$F$31 -> 8.3427311 | J24: =Cohorts!J21*Assumptions!$F$31 -> 9.8980698 | ... AL24: =Cohorts!AL21*Assumptions!$F$31 -> 170.33872
A25: Customer support | B25: € | C25: =Cohorts!C21*Assumptions!$F$32 -> 2.97 | D25: =Cohorts!D21*Assumptions!$F$32 -> 6.097641 | E25: =Cohorts!E21*Assumptions!$F$32 -> 9.4071552 | F25: =Cohorts!F21*Assumptions!$F$32 -> 12.924888 | G25: =Cohorts!G21*Assumptions!$F$32 -> 16.679556 | H25: =Cohorts!H21*Assumptions!$F$32 -> 20.702539 | I25: =Cohorts!I21*Assumptions!$F$32 -> 25.028193 | J25: =Cohorts!J21*Assumptions!$F$32 -> 29.694209 | ... AL25: =Cohorts!AL21*Assumptions!$F$32 -> 511.01615
A26: Payment processing | B26: € | C26: =C12*Assumptions!$F$33+C13*Assumptions!$F$34 -> 7.4646 | D26: =D12*Assumptions!$F$33+D13*Assumptions!$F$34 -> 11.420369 | E26: =E12*Assumptions!$F$33+E13*Assumptions!$F$34 -> 15.583261 | F26: =F12*Assumptions!$F$33+F13*Assumptions!$F$34 -> 19.985873 | G26: =G12*Assumptions!$F$33+G13*Assumptions!$F$34 -> 24.663662 | H26: =H12*Assumptions!$F$33+H13*Assumptions!$F$34 -> 29.655298 | I26: =I12*Assumptions!$F$33+I13*Assumptions!$F$34 -> 35.003054 | J26: =J12*Assumptions!$F$33+J13*Assumptions!$F$34 -> 40.753247 | ... AL26: =AL12*Assumptions!$F$33+AL13*Assumptions!$F$34 -> 634.10252
A27: Fixed platform cost | B27: € | C27: =Assumptions!$F$35 -> 70 | D27: =Assumptions!$F$35 -> 70 | E27: =Assumptions!$F$35 -> 70 | F27: =Assumptions!$F$35 -> 70 | G27: =Assumptions!$F$35 -> 70 | H27: =Assumptions!$F$35 -> 70 | I27: =Assumptions!$F$35 -> 70 | J27: =Assumptions!$F$35 -> 70 | ... AL27: =Assumptions!$F$35 -> 70
A28: Total cost of revenue | B28: € | C28: =SUM(C23:C27) -> 84.8896 | D28: =SUM(D23:D27) -> 96.664472 | E28: =SUM(E23:E27) -> 109.10115 | F28: =SUM(F23:F27) -> 122.29809 | G28: =SUM(G23:G27) -> 136.36255 | H28: =SUM(H23:H27) -> 151.41164 | I28: =SUM(I23:I27) -> 167.57354 | J28: =SUM(J23:J27) -> 184.98877 | ... AL28: =SUM(AL23:AL27) -> 1981.6429
A30: Gross profit | B30: € | C30: =C18-C28 -> 29.9504 | D30: =D18-D28 -> 138.9209 | E30: =E18-E28 -> 254.06414 | F30: =F18-F28 -> 376.29106 | G30: =G18-G28 -> 506.59399 | H30: =H18-H28 -> 646.05658 | I30: =I18-I28 -> 795.86472 | J30: =J18-J28 -> 957.3188 | ... AL30: =AL18-AL28 -> 17545.564
A31: Gross margin | B31: % | C31: =IF(C18=0,0,C30/C18) -> 0.26080111 | D31: =IF(D18=0,0,D30/D18) -> 0.5896839 | E31: =IF(E18=0,0,E30/E18) -> 0.69958266 | F31: =IF(F18=0,0,F30/F18) -> 0.75471169 | G31: =IF(G18=0,0,G30/G18) -> 0.78791327 | H31: =IF(H18=0,0,H30/H18) -> 0.81013457 | I31: =IF(I18=0,0,I30/I18) -> 0.82606718 | J31: =IF(J18=0,0,J30/J18) -> 0.83805695 | ... AL31: =IF(AL18=0,0,AL30/AL18) -> 0.89851888
A33: OPERATING EXPENSES
A34: Paid marketing | B34: € | C34: =Cohorts!C8 -> 500 | D34: =Cohorts!D8 -> 540 | E34: =Cohorts!E8 -> 583.2 | F34: =Cohorts!F8 -> 629.856 | G34: =Cohorts!G8 -> 680.24448 | H34: =Cohorts!H8 -> 734.66404 | I34: =Cohorts!I8 -> 793.43716 | J34: =Cohorts!J8 -> 856.91213 | ... AL34: =Cohorts!AL8 -> 6000
A35: Founder compensation | B35: € | C35: =IF(C5>=Assumptions!$F$38,Assumptions!$F$37,0) -> 0 | D35: =IF(D5>=Assumptions!$F$38,Assumptions!$F$37,0) -> 0 | E35: =IF(E5>=Assumptions!$F$38,Assumptions!$F$37,0) -> 0 | F35: =IF(F5>=Assumptions!$F$38,Assumptions!$F$37,0) -> 0 | G35: =IF(G5>=Assumptions!$F$38,Assumptions!$F$37,0) -> 0 | H35: =IF(H5>=Assumptions!$F$38,Assumptions!$F$37,0) -> 0 | I35: =IF(I5>=Assumptions!$F$38,Assumptions!$F$37,0) -> 0 | J35: =IF(J5>=Assumptions!$F$38,Assumptions!$F$37,0) -> 0 | ... AL35: =IF(AL5>=Assumptions!$F$38,Assumptions!$F$37,0) -> 2500
A36: Tools & software | B36: € | C36: =Assumptions!$F$39*(1+Assumptions!$F$41)^(C5-1) -> 120 | D36: =Assumptions!$F$39*(1+Assumptions!$F$41)^(D5-1) -> 120.6 | E36: =Assumptions!$F$39*(1+Assumptions!$F$41)^(E5-1) -> 121.203 | F36: =Assumptions!$F$39*(1+Assumptions!$F$41)^(F5-1) -> 121.80902 | G36: =Assumptions!$F$39*(1+Assumptions!$F$41)^(G5-1) -> 122.41806 | H36: =Assumptions!$F$39*(1+Assumptions!$F$41)^(H5-1) -> 123.03015 | I36: =Assumptions!$F$39*(1+Assumptions!$F$41)^(I5-1) -> 123.6453 | J36: =Assumptions!$F$39*(1+Assumptions!$F$41)^(J5-1) -> 124.26353 | ... AL36: =Assumptions!$F$39*(1+Assumptions!$F$41)^(AL5-1) -> 142.88723
A37: Legal, accounting & admin | B37: € | C37: =Assumptions!$F$40*(1+Assumptions!$F$41)^(C5-1) -> 80 | D37: =Assumptions!$F$40*(1+Assumptions!$F$41)^(D5-1) -> 80.4 | E37: =Assumptions!$F$40*(1+Assumptions!$F$41)^(E5-1) -> 80.802 | F37: =Assumptions!$F$40*(1+Assumptions!$F$41)^(F5-1) -> 81.20601 | G37: =Assumptions!$F$40*(1+Assumptions!$F$41)^(G5-1) -> 81.61204 | H37: =Assumptions!$F$40*(1+Assumptions!$F$41)^(H5-1) -> 82.0201 | I37: =Assumptions!$F$40*(1+Assumptions!$F$41)^(I5-1) -> 82.430201 | J37: =Assumptions!$F$40*(1+Assumptions!$F$41)^(J5-1) -> 82.842352 | ... AL37: =Assumptions!$F$40*(1+Assumptions!$F$41)^(AL5-1) -> 95.258151
A38: Total operating expenses | B38: € | C38: =SUM(C34:C37) -> 700 | D38: =SUM(D34:D37) -> 741 | E38: =SUM(E34:E37) -> 785.205 | F38: =SUM(F34:F37) -> 832.87103 | G38: =SUM(G34:G37) -> 884.27458 | H38: =SUM(H34:H37) -> 939.71429 | I38: =SUM(I34:I37) -> 999.51266 | J38: =SUM(J34:J37) -> 1064.018 | ... AL38: =SUM(AL34:AL37) -> 8738.1454
A40: EBITDA | B40: € | C40: =C30-C38 -> -670.0496 | D40: =D30-D38 -> -602.0791 | E40: =E30-E38 -> -531.14086 | F40: =F30-F38 -> -456.57997 | G40: =G30-G38 -> -377.68059 | H40: =H30-H38 -> -293.65771 | I40: =I30-I38 -> -203.64794 | J40: =J30-J38 -> -106.69921 | ... AL40: =AL30-AL38 -> 8807.4186
A41: EBITDA margin | B41: % | C41: =IF(C18=0,0,C40/C18) -> -5.834636 | D41: =IF(D18=0,0,D40/D18) -> -2.5556727 | E41: =IF(E18=0,0,E40/E18) -> -1.462532 | F41: =IF(F18=0,0,F40/F18) -> -0.9157439 | G41: =IF(G18=0,0,G40/G18) -> -0.58741231 | H41: =IF(H18=0,0,H40/H18) -> -0.36823751 | I41: =IF(I18=0,0,I40/I18) -> -0.21137622 | J41: =IF(J18=0,0,J40/J18) -> -0.093406729 | ... AL41: =IF(AL18=0,0,AL40/AL18) -> 0.4510332
A42: Cumulative EBITDA | B42: € | C42: =C40 -> -670.0496 | D42: =C42+D40 -> -1272.1287 | E42: =D42+E40 -> -1803.2696 | F42: =E42+F40 -> -2259.8495 | G42: =F42+G40 -> -2637.5301 | H42: =G42+H40 -> -2931.1878 | I42: =H42+I40 -> -3134.8358 | J42: =I42+J40 -> -3241.535 | K42: =J42+K40 -> -3243.2944 | ... AL42: =AK42+AL40 -> 49272.658
A43: MEMO
A44: Month flag — EBITDA positive | B44: # | C44: =IF(C40>0,C5,9999) -> 9999 | D44: =IF(D40>0,D5,9999) -> 9999 | E44: =IF(E40>0,E5,9999) -> 9999 | F44: =IF(F40>0,F5,9999) -> 9999 | G44: =IF(G40>0,G5,9999) -> 9999 | H44: =IF(H40>0,H5,9999) -> 9999 | I44: =IF(I40>0,I5,9999) -> 9999 | J44: =IF(J40>0,J5,9999) -> 9999 | ... AL44: =IF(AL40>0,AL5,9999) -> 36
A45: 9999 = not yet positive. Dashboard takes the MIN of this row.

Sheet Cash Flow
A2: CASH FLOW & DEFERRED REVENUE
A3: Card payments are collected on charge, so collections equal billings. The gap between cash and EBITDA is the annual prepayment, and it is checked every month.
A5: Month index | B5: # | C5: 1 | D5: 2 | E5: 3 | F5: 4 | G5: 5 | H5: 6 | I5: 7 | J5: 8 | K5: 9 | L5: 10 | M5: 11 | N5: 12 | O5: 13 | P5: 14 | Q5: 15 | R5: 16 | S5: 17 | T5: 18 | U5: 19 | V5: 20 | W5: 21 | X5: 22 | Y5: 23 | Z5: 24 | AA5: 25 | AB5: 26 | AC5: 27 | AD5: 28 | AE5: 29 | AF5: 30 | AG5: 31 | AH5: 32 | AI5: 33 | AJ5: 34 | AK5: 35 | AL5: 36
A7: CASH WALK
A8: Opening cash | B8: € | C8: =Assumptions!$F$43 -> 5000 | D8: =C13 -> 4547.7504 | E8: =D13 -> 4165.686 | F8: =E13 -> 3856.9798 | G8: =F13 -> 3625.4939 | H8: =G13 -> 3475.8452 | I8: =H13 -> 3413.4789 | J8: =I13 -> 3444.7522 | K8: =J13 -> 3577.0291 | ... AL8: =AK13 -> 72149.53
A9: Collections (= total billings) | B9: € | C9: ='P&L'!C12 -> 332.64 | D9: ='P&L'!D12 -> 455.60011 | E9: ='P&L'!E12 -> 585.59989 | F9: ='P&L'!F12 -> 723.68325 | G9: ='P&L'!G12 -> 870.98844 | H9: ='P&L'!H12 -> 1028.7596 | I9: ='P&L'!I12 -> 1198.3595 | J9: ='P&L'!J12 -> 1381.2838 | ... AL9: ='P&L'!AL12 -> 20698.672
A10: Cost of revenue paid | B10: € | C10: =-'P&L'!C28 -> -84.8896 | D10: =-'P&L'!D28 -> -96.664472 | E10: =-'P&L'!E28 -> -109.10115 | F10: =-'P&L'!F28 -> -122.29809 | G10: =-'P&L'!G28 -> -136.36255 | H10: =-'P&L'!H28 -> -151.41164 | I10: =-'P&L'!I28 -> -167.57354 | J10: =-'P&L'!J28 -> -184.98877 | ... AL10: =-'P&L'!AL28 -> -1981.6429
A11: Operating expenses paid | B11: € | C11: =-'P&L'!C38 -> -700 | D11: =-'P&L'!D38 -> -741 | E11: =-'P&L'!E38 -> -785.205 | F11: =-'P&L'!F38 -> -832.87103 | G11: =-'P&L'!G38 -> -884.27458 | H11: =-'P&L'!H38 -> -939.71429 | I11: =-'P&L'!I38 -> -999.51266 | J11: =-'P&L'!J38 -> -1064.018 | ... AL11: =-'P&L'!AL38 -> -8738.1454
A12: Net cash flow | B12: € | C12: =SUM(C9:C11) -> -452.2496 | D12: =SUM(D9:D11) -> -382.06436 | E12: =SUM(E9:E11) -> -308.70625 | F12: =SUM(F9:F11) -> -231.48586 | G12: =SUM(G9:G11) -> -149.64869 | H12: =SUM(H9:H11) -> -62.366348 | I12: =SUM(I9:I11) -> 31.273278 | J12: =SUM(J9:J11) -> 132.27697 | ... AL12: =SUM(AL9:AL11) -> 9978.8836
A13: Closing cash | B13: € | C13: =C8+C12 -> 4547.7504 | D13: =D8+D12 -> 4165.686 | E13: =E8+E12 -> 3856.9798 | F13: =F8+F12 -> 3625.4939 | G13: =G8+G12 -> 3475.8452 | H13: =H8+H12 -> 3413.4789 | I13: =I8+I12 -> 3444.7522 | J13: =J8+J12 -> 3577.0291 | ... AL13: =AL8+AL12 -> 82128.413
A15: DEFERRED REVENUE ROLLFORWARD (annual prepayments)
A16: Opening deferred revenue | B16: € | C16: =0 -> 0 | D16: =C19 -> 217.8 | E16: =D19 -> 437.81474 | F16: =E19 -> 660.24935 | G16: =F19 -> 885.34345 | H16: =G19 -> 1113.3754 | I16: =H19 -> 1344.6667 | J16: =I19 -> 1579.5879 | K16: =J19 -> 1818.5641 | ... AL16: =AK19 -> 26684.29
A17: Annual billings received | B17: € | C17: ='P&L'!C11 -> 237.6 | D17: ='P&L'!D11 -> 261.61608 | E17: ='P&L'!E11 -> 288.03922 | F17: ='P&L'!F11 -> 317.12587 | G17: ='P&L'!G11 -> 349.16036 | H17: ='P&L'!H11 -> 384.45799 | I17: ='P&L'!I11 -> 423.36856 | J17: ='P&L'!J11 -> 466.2802 | ... AL17: ='P&L'!AL11 -> 5738.6609
A18: Recognised into revenue | B18: € | C18: =-'P&L'!C17 -> -19.8 | D18: =-'P&L'!D17 -> -41.60134 | E18: =-'P&L'!E17 -> -65.604608 | F18: =-'P&L'!F17 -> -92.031764 | G18: =-'P&L'!G17 -> -121.12846 | H18: =-'P&L'!H17 -> -153.16663 | I18: =-'P&L'!I17 -> -188.44734 | J18: =-'P&L'!J17 -> -227.30402 | ... AL18: =-'P&L'!AL17 -> -4567.1958
A19: Closing deferred revenue | B19: € | C19: =SUM(C16:C18) -> 217.8 | D19: =SUM(D16:D18) -> 437.81474 | E19: =SUM(E16:E18) -> 660.24935 | F19: =SUM(F16:F18) -> 885.34345 | G19: =SUM(G16:G18) -> 1113.3754 | H19: =SUM(H16:H18) -> 1344.6667 | I19: =SUM(I16:I18) -> 1579.5879 | J19: =SUM(J16:J18) -> 1818.5641 | ... AL19: =SUM(AL16:AL18) -> 27855.755
A21: INTEGRITY CHECK
A22: EBITDA | B22: € | C22: ='P&L'!C40 -> -670.0496 | D22: ='P&L'!D40 -> -602.0791 | E22: ='P&L'!E40 -> -531.14086 | F22: ='P&L'!F40 -> -456.57997 | G22: ='P&L'!G40 -> -377.68059 | H22: ='P&L'!H40 -> -293.65771 | I22: ='P&L'!I40 -> -203.64794 | J22: ='P&L'!J40 -> -106.69921 | ... AL22: ='P&L'!AL40 -> 8807.4186
A23: Δ deferred revenue | B23: € | C23: =C19-C16 -> 217.8 | D23: =D19-D16 -> 220.01474 | E23: =E19-E16 -> 222.43461 | F23: =F19-F16 -> 225.09411 | G23: =G19-G16 -> 228.0319 | H23: =H19-H16 -> 231.29136 | I23: =I19-I16 -> 234.92122 | J23: =J19-J16 -> 238.97618 | ... AL23: =AL19-AL16 -> 1171.4651
A24: Check: net cash − EBITDA − Δdeferred | B24: € | C24: =ROUND(C12-C22-C23,6) -> 0 | D24: =ROUND(D12-D22-D23,6) -> 0 | E24: =ROUND(E12-E22-E23,6) -> 0 | F24: =ROUND(F12-F22-F23,6) -> 0 | G24: =ROUND(G12-G22-G23,6) -> 0 | H24: =ROUND(H12-H22-H23,6) -> 0 | I24: =ROUND(I12-I22-I23,6) -> 0 | J24: =ROUND(J12-J22-J23,6) -> 0 | ... AL24: =ROUND(AL12-AL22-AL23,6) -> 0
A25: Must be zero in every month. Any non-zero cell means the P&L and the cash walk have come apart — stop and fix before reading anything else.
A26: MEMO
A27: Month flag — net cash flow positive | B27: # | C27: =IF(C12>0,C5,9999) -> 9999 | D27: =IF(D12>0,D5,9999) -> 9999 | E27: =IF(E12>0,E5,9999) -> 9999 | F27: =IF(F12>0,F5,9999) -> 9999 | G27: =IF(G12>0,G5,9999) -> 9999 | H27: =IF(H12>0,H5,9999) -> 9999 | I27: =IF(I12>0,I5,9999) -> 7 | J27: =IF(J12>0,J5,9999) -> 8 | ... AL27: =IF(AL12>0,AL5,9999) -> 36

Sheet Unit Economics
A2: UNIT ECONOMICS
A3: Steady-state economics on the live scenario, then two grids showing how fast the verdict changes.
A5: VALUE OF A CUSTOMER
A6: Blended ARPU | B6: € / month | C6: =Assumptions!$F$48 -> 11.6 | L6: Across monthly and annual plans.
A7: Gross margin (month 36, at scale) | B7: % | C7: ='P&L'!AL31 -> 0.89851888 | L7: Taken at month 36 so fixed platform cost is spread over the mature base — not the month-1 margin.
A8: Gross profit per customer / month | B8: € | C8: =C6*C7 -> 10.422819
A9: Blended monthly churn | B9: % | C9: =Assumptions!$F$51 -> 0.053857106
A10: Average customer lifetime | B10: months | C10: =Assumptions!$F$52 -> 18.567652 | L10: 1 / blended churn.
A11: LTV | B11: € | C11: =C8*C10 -> 193.52727 | L11: Gross-profit LTV, undiscounted.
A13: COST OF A CUSTOMER
A14: Paid CAC (funnel maths) | B14: € | C14: =Assumptions!$F$53 -> 90.909091 | L14: CPC / (signup rate x trial-to-paid). What the marginal paid customer costs.
A15: Total paid marketing, 36 months | B15: € | C15: =SUM('P&L'!C34:AL34) -> 90975.31
A16: Total new customers, 36 months | B16: # | C16: =SUM(Cohorts!C14:AL14) -> 2599.5125
A17: Blended CAC | B17: € | C17: =IF(C16=0,0,C15/C16) -> 34.997065 | L17: All marketing spend over all new customers, including the organic and referral ones that cost nothing. Flattering — quote paid CAC to anyone serious.
A19: VERDICT
A20: LTV : CAC — paid | B20: x | C20: =IF(C14=0,0,C11/C14) -> 2.1288 | L20: The honest one. Below 3.0x, paid acquisition does not fund itself.
A21: LTV : CAC — blended | B21: x | C21: =IF(C17=0,0,C11/C17) -> 5.5298144 | L21: Includes free channels.
A22: CAC payback — paid | B22: months | C22: =IF(C8=0,0,C14/C8) -> 8.7221213 | L22: Months of gross profit to repay one paid customer. Must be comfortably below average lifetime (row 10) or the customer leaves before repaying.
A23: CAC payback — blended | B23: months | C23: =IF(C8=0,0,C17/C8) -> 3.3577351
A24: Profitable months after payback | B24: months | C24: =C10-C22 -> 9.8455307 | L24: Average lifetime minus payback. This is the only window in which a customer actually makes money. Negative means the average customer leaves still owing you their acquisition cost.
A27: SENSITIVITY — LTV : CAC (paid)
A28: Blended monthly churn ↓ / Trial-to-paid → | L28: Grid recomputes from the live ARPU, gross margin, CPC and signup rate. Green ≥ 3.0x, amber 2.0–3.0x, red < 2.0x — the standard venture bar.
D29: 0.12 | E29: 0.15 | F29: 0.18 | G29: 0.22 | H29: 0.25 | I29: 0.28 | J29: 0.32
C30: 0.04 | D30: =IF(OR($C30=0,D$29=0,Assumptions!$F$19=0),0,(($C$6*$C$7)/$C30)/(Assumptions!$F$19/(Assumptions!$F$20*D$29))) -> 1.5634228 | E30: =IF(OR($C30=0,E$29=0,Assumptions!$F$19=0),0,(($C$6*$C$7)/$C30)/(Assumptions!$F$19/(Assumptions!$F$20*E$29))) -> 1.9542786 | F30: =IF(OR($C30=0,F$29=0,Assumptions!$F$19=0),0,(($C$6*$C$7)/$C30)/(Assumptions!$F$19/(Assumptions!$F$20*F$29))) -> 2.3451343 | G30: =IF(OR($C30=0,G$29=0,Assumptions!$F$19=0),0,(($C$6*$C$7)/$C30)/(Assumptions!$F$19/(Assumptions!$F$20*G$29))) -> 2.8662752 | H30: =IF(OR($C30=0,H$29=0,Assumptions!$F$19=0),0,(($C$6*$C$7)/$C30)/(Assumptions!$F$19/(Assumptions!$F$20*H$29))) -> 3.2571309 | I30: =IF(OR($C30=0,I$29=0,Assumptions!$F$19=0),0,(($C$6*$C$7)/$C30)/(Assumptions!$F$19/(Assumptions!$F$20*I$29))) -> 3.6479866 | J30: =IF(OR($C30=0,J$29=0,Assumptions!$F$19=0),0,(($C$6*$C$7)/$C30)/(Assumptions!$F$19/(Assumptions!$F$20*J$29))) -> 4.1691276
C31: 0.045 | D31: =IF(OR($C31=0,D$29=0,Assumptions!$F$19=0),0,(($C$6*$C$7)/$C31)/(Assumptions!$F$19/(Assumptions!$F$20*D$29))) -> 1.3897092 | E31: =IF(OR($C31=0,E$29=0,Assumptions!$F$19=0),0,(($C$6*$C$7)/$C31)/(Assumptions!$F$19/(Assumptions!$F$20*E$29))) -> 1.7371365 | F31: =IF(OR($C31=0,F$29=0,Assumptions!$F$19=0),0,(($C$6*$C$7)/$C31)/(Assumptions!$F$19/(Assumptions!$F$20*F$29))) -> 2.0845638 | G31: =IF(OR($C31=0,G$29=0,Assumptions!$F$19=0),0,(($C$6*$C$7)/$C31)/(Assumptions!$F$19/(Assumptions!$F$20*G$29))) -> 2.5478002 | H31: =IF(OR($C31=0,H$29=0,Assumptions!$F$19=0),0,(($C$6*$C$7)/$C31)/(Assumptions!$F$19/(Assumptions!$F$20*H$29))) -> 2.8952275 | I31: =IF(OR($C31=0,I$29=0,Assumptions!$F$19=0),0,(($C$6*$C$7)/$C31)/(Assumptions!$F$19/(Assumptions!$F$20*I$29))) -> 3.2426548 | J31: =IF(OR($C31=0,J$29=0,Assumptions!$F$19=0),0,(($C$6*$C$7)/$C31)/(Assumptions!$F$19/(Assumptions!$F$20*J$29))) -> 3.7058912
C32: 0.05 | D32: =IF(OR($C32=0,D$29=0,Assumptions!$F$19=0),0,(($C$6*$C$7)/$C32)/(Assumptions!$F$19/(Assumptions!$F$20*D$29))) -> 1.2507383 | E32: =IF(OR($C32=0,E$29=0,Assumptions!$F$19=0),0,(($C$6*$C$7)/$C32)/(Assumptions!$F$19/(Assumptions!$F$20*E$29))) -> 1.5634228 | F32: =IF(OR($C32=0,F$29=0,Assumptions!$F$19=0),0,(($C$6*$C$7)/$C32)/(Assumptions!$F$19/(Assumptions!$F$20*F$29))) -> 1.8761074 | G32: =IF(OR($C32=0,G$29=0,Assumptions!$F$19=0),0,(($C$6*$C$7)/$C32)/(Assumptions!$F$19/(Assumptions!$F$20*G$29))) -> 2.2930202 | H32: =IF(OR($C32=0,H$29=0,Assumptions!$F$19=0),0,(($C$6*$C$7)/$C32)/(Assumptions!$F$19/(Assumptions!$F$20*H$29))) -> 2.6057047 | I32: =IF(OR($C32=0,I$29=0,Assumptions!$F$19=0),0,(($C$6*$C$7)/$C32)/(Assumptions!$F$19/(Assumptions!$F$20*I$29))) -> 2.9183893 | J32: =IF(OR($C32=0,J$29=0,Assumptions!$F$19=0),0,(($C$6*$C$7)/$C32)/(Assumptions!$F$19/(Assumptions!$F$20*J$29))) -> 3.3353021
C33: 0.06 | D33: =IF(OR($C33=0,D$29=0,Assumptions!$F$19=0),0,(($C$6*$C$7)/$C33)/(Assumptions!$F$19/(Assumptions!$F$20*D$29))) -> 1.0422819 | E33: =IF(OR($C33=0,E$29=0,Assumptions!$F$19=0),0,(($C$6*$C$7)/$C33)/(Assumptions!$F$19/(Assumptions!$F$20*E$29))) -> 1.3028524 | F33: =IF(OR($C33=0,F$29=0,Assumptions!$F$19=0),0,(($C$6*$C$7)/$C33)/(Assumptions!$F$19/(Assumptions!$F$20*F$29))) -> 1.5634228 | G33: =IF(OR($C33=0,G$29=0,Assumptions!$F$19=0),0,(($C$6*$C$7)/$C33)/(Assumptions!$F$19/(Assumptions!$F$20*G$29))) -> 1.9108501 | H33: =IF(OR($C33=0,H$29=0,Assumptions!$F$19=0),0,(($C$6*$C$7)/$C33)/(Assumptions!$F$19/(Assumptions!$F$20*H$29))) -> 2.1714206 | I33: =IF(OR($C33=0,I$29=0,Assumptions!$F$19=0),0,(($C$6*$C$7)/$C33)/(Assumptions!$F$19/(Assumptions!$F$20*I$29))) -> 2.4319911 | J33: =IF(OR($C33=0,J$29=0,Assumptions!$F$19=0),0,(($C$6*$C$7)/$C33)/(Assumptions!$F$19/(Assumptions!$F$20*J$29))) -> 2.7794184
C34: 0.07 | D34: =IF(OR($C34=0,D$29=0,Assumptions!$F$19=0),0,(($C$6*$C$7)/$C34)/(Assumptions!$F$19/(Assumptions!$F$20*D$29))) -> 0.89338448 | E34: =IF(OR($C34=0,E$29=0,Assumptions!$F$19=0),0,(($C$6*$C$7)/$C34)/(Assumptions!$F$19/(Assumptions!$F$20*E$29))) -> 1.1167306 | F34: =IF(OR($C34=0,F$29=0,Assumptions!$F$19=0),0,(($C$6*$C$7)/$C34)/(Assumptions!$F$19/(Assumptions!$F$20*F$29))) -> 1.3400767 | G34: =IF(OR($C34=0,G$29=0,Assumptions!$F$19=0),0,(($C$6*$C$7)/$C34)/(Assumptions!$F$19/(Assumptions!$F$20*G$29))) -> 1.6378716 | H34: =IF(OR($C34=0,H$29=0,Assumptions!$F$19=0),0,(($C$6*$C$7)/$C34)/(Assumptions!$F$19/(Assumptions!$F$20*H$29))) -> 1.8612177 | I34: =IF(OR($C34=0,I$29=0,Assumptions!$F$19=0),0,(($C$6*$C$7)/$C34)/(Assumptions!$F$19/(Assumptions!$F$20*I$29))) -> 2.0845638 | J34: =IF(OR($C34=0,J$29=0,Assumptions!$F$19=0),0,(($C$6*$C$7)/$C34)/(Assumptions!$F$19/(Assumptions!$F$20*J$29))) -> 2.3823586
C35: 0.08 | D35: =IF(OR($C35=0,D$29=0,Assumptions!$F$19=0),0,(($C$6*$C$7)/$C35)/(Assumptions!$F$19/(Assumptions!$F$20*D$29))) -> 0.78171142 | E35: =IF(OR($C35=0,E$29=0,Assumptions!$F$19=0),0,(($C$6*$C$7)/$C35)/(Assumptions!$F$19/(Assumptions!$F$20*E$29))) -> 0.97713928 | F35: =IF(OR($C35=0,F$29=0,Assumptions!$F$19=0),0,(($C$6*$C$7)/$C35)/(Assumptions!$F$19/(Assumptions!$F$20*F$29))) -> 1.1725671 | G35: =IF(OR($C35=0,G$29=0,Assumptions!$F$19=0),0,(($C$6*$C$7)/$C35)/(Assumptions!$F$19/(Assumptions!$F$20*G$29))) -> 1.4331376 | H35: =IF(OR($C35=0,H$29=0,Assumptions!$F$19=0),0,(($C$6*$C$7)/$C35)/(Assumptions!$F$19/(Assumptions!$F$20*H$29))) -> 1.6285655 | I35: =IF(OR($C35=0,I$29=0,Assumptions!$F$19=0),0,(($C$6*$C$7)/$C35)/(Assumptions!$F$19/(Assumptions!$F$20*I$29))) -> 1.8239933 | J35: =IF(OR($C35=0,J$29=0,Assumptions!$F$19=0),0,(($C$6*$C$7)/$C35)/(Assumptions!$F$19/(Assumptions!$F$20*J$29))) -> 2.0845638
C36: 0.09 | D36: =IF(OR($C36=0,D$29=0,Assumptions!$F$19=0),0,(($C$6*$C$7)/$C36)/(Assumptions!$F$19/(Assumptions!$F$20*D$29))) -> 0.6948546 | E36: =IF(OR($C36=0,E$29=0,Assumptions!$F$19=0),0,(($C$6*$C$7)/$C36)/(Assumptions!$F$19/(Assumptions!$F$20*E$29))) -> 0.86856825 | F36: =IF(OR($C36=0,F$29=0,Assumptions!$F$19=0),0,(($C$6*$C$7)/$C36)/(Assumptions!$F$19/(Assumptions!$F$20*F$29))) -> 1.0422819 | G36: =IF(OR($C36=0,G$29=0,Assumptions!$F$19=0),0,(($C$6*$C$7)/$C36)/(Assumptions!$F$19/(Assumptions!$F$20*G$29))) -> 1.2739001 | H36: =IF(OR($C36=0,H$29=0,Assumptions!$F$19=0),0,(($C$6*$C$7)/$C36)/(Assumptions!$F$19/(Assumptions!$F$20*H$29))) -> 1.4476137 | I36: =IF(OR($C36=0,I$29=0,Assumptions!$F$19=0),0,(($C$6*$C$7)/$C36)/(Assumptions!$F$19/(Assumptions!$F$20*I$29))) -> 1.6213274 | J36: =IF(OR($C36=0,J$29=0,Assumptions!$F$19=0),0,(($C$6*$C$7)/$C36)/(Assumptions!$F$19/(Assumptions!$F$20*J$29))) -> 1.8529456
A39: SENSITIVITY — CAC payback (months, paid)
A40: Blended CPC ↓ / Trial-to-paid → | L40: Compare every cell against average customer lifetime on row 10. Any cell above it means the customer churns before paying you back.
D41: 0.12 | E41: 0.15 | F41: 0.18 | G41: 0.22 | H41: 0.25 | I41: 0.28 | J41: 0.32
C42: 0.4 | D42: =IF(OR(D$41=0,$C$6*$C$7=0),0,($C42/(Assumptions!$F$20*D$41))/($C$6*$C$7)) -> 7.9952778 | E42: =IF(OR(E$41=0,$C$6*$C$7=0),0,($C42/(Assumptions!$F$20*E$41))/($C$6*$C$7)) -> 6.3962223 | F42: =IF(OR(F$41=0,$C$6*$C$7=0),0,($C42/(Assumptions!$F$20*F$41))/($C$6*$C$7)) -> 5.3301852 | G42: =IF(OR(G$41=0,$C$6*$C$7=0),0,($C42/(Assumptions!$F$20*G$41))/($C$6*$C$7)) -> 4.3610606 | H42: =IF(OR(H$41=0,$C$6*$C$7=0),0,($C42/(Assumptions!$F$20*H$41))/($C$6*$C$7)) -> 3.8377334 | I42: =IF(OR(I$41=0,$C$6*$C$7=0),0,($C42/(Assumptions!$F$20*I$41))/($C$6*$C$7)) -> 3.4265476 | J42: =IF(OR(J$41=0,$C$6*$C$7=0),0,($C42/(Assumptions!$F$20*J$41))/($C$6*$C$7)) -> 2.9982292
C43: 0.6 | D43: =IF(OR(D$41=0,$C$6*$C$7=0),0,($C43/(Assumptions!$F$20*D$41))/($C$6*$C$7)) -> 11.992917 | E43: =IF(OR(E$41=0,$C$6*$C$7=0),0,($C43/(Assumptions!$F$20*E$41))/($C$6*$C$7)) -> 9.5943334 | F43: =IF(OR(F$41=0,$C$6*$C$7=0),0,($C43/(Assumptions!$F$20*F$41))/($C$6*$C$7)) -> 7.9952778 | G43: =IF(OR(G$41=0,$C$6*$C$7=0),0,($C43/(Assumptions!$F$20*G$41))/($C$6*$C$7)) -> 6.5415909 | H43: =IF(OR(H$41=0,$C$6*$C$7=0),0,($C43/(Assumptions!$F$20*H$41))/($C$6*$C$7)) -> 5.7566 | I43: =IF(OR(I$41=0,$C$6*$C$7=0),0,($C43/(Assumptions!$F$20*I$41))/($C$6*$C$7)) -> 5.1398215 | J43: =IF(OR(J$41=0,$C$6*$C$7=0),0,($C43/(Assumptions!$F$20*J$41))/($C$6*$C$7)) -> 4.4973438
C44: 0.8 | D44: =IF(OR(D$41=0,$C$6*$C$7=0),0,($C44/(Assumptions!$F$20*D$41))/($C$6*$C$7)) -> 15.990556 | E44: =IF(OR(E$41=0,$C$6*$C$7=0),0,($C44/(Assumptions!$F$20*E$41))/($C$6*$C$7)) -> 12.792445 | F44: =IF(OR(F$41=0,$C$6*$C$7=0),0,($C44/(Assumptions!$F$20*F$41))/($C$6*$C$7)) -> 10.66037 | G44: =IF(OR(G$41=0,$C$6*$C$7=0),0,($C44/(Assumptions!$F$20*G$41))/($C$6*$C$7)) -> 8.7221213 | H44: =IF(OR(H$41=0,$C$6*$C$7=0),0,($C44/(Assumptions!$F$20*H$41))/($C$6*$C$7)) -> 7.6754667 | I44: =IF(OR(I$41=0,$C$6*$C$7=0),0,($C44/(Assumptions!$F$20*I$41))/($C$6*$C$7)) -> 6.8530953 | J44: =IF(OR(J$41=0,$C$6*$C$7=0),0,($C44/(Assumptions!$F$20*J$41))/($C$6*$C$7)) -> 5.9964584
C45: 1 | D45: =IF(OR(D$41=0,$C$6*$C$7=0),0,($C45/(Assumptions!$F$20*D$41))/($C$6*$C$7)) -> 19.988195 | E45: =IF(OR(E$41=0,$C$6*$C$7=0),0,($C45/(Assumptions!$F$20*E$41))/($C$6*$C$7)) -> 15.990556 | F45: =IF(OR(F$41=0,$C$6*$C$7=0),0,($C45/(Assumptions!$F$20*F$41))/($C$6*$C$7)) -> 13.325463 | G45: =IF(OR(G$41=0,$C$6*$C$7=0),0,($C45/(Assumptions!$F$20*G$41))/($C$6*$C$7)) -> 10.902652 | H45: =IF(OR(H$41=0,$C$6*$C$7=0),0,($C45/(Assumptions!$F$20*H$41))/($C$6*$C$7)) -> 9.5943334 | I45: =IF(OR(I$41=0,$C$6*$C$7=0),0,($C45/(Assumptions!$F$20*I$41))/($C$6*$C$7)) -> 8.5663691 | J45: =IF(OR(J$41=0,$C$6*$C$7=0),0,($C45/(Assumptions!$F$20*J$41))/($C$6*$C$7)) -> 7.495573
C46: 1.2 | D46: =IF(OR(D$41=0,$C$6*$C$7=0),0,($C46/(Assumptions!$F$20*D$41))/($C$6*$C$7)) -> 23.985833 | E46: =IF(OR(E$41=0,$C$6*$C$7=0),0,($C46/(Assumptions!$F$20*E$41))/($C$6*$C$7)) -> 19.188667 | F46: =IF(OR(F$41=0,$C$6*$C$7=0),0,($C46/(Assumptions!$F$20*F$41))/($C$6*$C$7)) -> 15.990556 | G46: =IF(OR(G$41=0,$C$6*$C$7=0),0,($C46/(Assumptions!$F$20*G$41))/($C$6*$C$7)) -> 13.083182 | H46: =IF(OR(H$41=0,$C$6*$C$7=0),0,($C46/(Assumptions!$F$20*H$41))/($C$6*$C$7)) -> 11.5132 | I46: =IF(OR(I$41=0,$C$6*$C$7=0),0,($C46/(Assumptions!$F$20*I$41))/($C$6*$C$7)) -> 10.279643 | J46: =IF(OR(J$41=0,$C$6*$C$7=0),0,($C46/(Assumptions!$F$20*J$41))/($C$6*$C$7)) -> 8.9946876
C47: 1.5 | D47: =IF(OR(D$41=0,$C$6*$C$7=0),0,($C47/(Assumptions!$F$20*D$41))/($C$6*$C$7)) -> 29.982292 | E47: =IF(OR(E$41=0,$C$6*$C$7=0),0,($C47/(Assumptions!$F$20*E$41))/($C$6*$C$7)) -> 23.985833 | F47: =IF(OR(F$41=0,$C$6*$C$7=0),0,($C47/(Assumptions!$F$20*F$41))/($C$6*$C$7)) -> 19.988195 | G47: =IF(OR(G$41=0,$C$6*$C$7=0),0,($C47/(Assumptions!$F$20*G$41))/($C$6*$C$7)) -> 16.353977 | H47: =IF(OR(H$41=0,$C$6*$C$7=0),0,($C47/(Assumptions!$F$20*H$41))/($C$6*$C$7)) -> 14.3915 | I47: =IF(OR(I$41=0,$C$6*$C$7=0),0,($C47/(Assumptions!$F$20*I$41))/($C$6*$C$7)) -> 12.849554 | J47: =IF(OR(J$41=0,$C$6*$C$7=0),0,($C47/(Assumptions!$F$20*J$41))/($C$6*$C$7)) -> 11.243359
C48: 2 | D48: =IF(OR(D$41=0,$C$6*$C$7=0),0,($C48/(Assumptions!$F$20*D$41))/($C$6*$C$7)) -> 39.976389 | E48: =IF(OR(E$41=0,$C$6*$C$7=0),0,($C48/(Assumptions!$F$20*E$41))/($C$6*$C$7)) -> 31.981111 | F48: =IF(OR(F$41=0,$C$6*$C$7=0),0,($C48/(Assumptions!$F$20*F$41))/($C$6*$C$7)) -> 26.650926 | G48: =IF(OR(G$41=0,$C$6*$C$7=0),0,($C48/(Assumptions!$F$20*G$41))/($C$6*$C$7)) -> 21.805303 | H48: =IF(OR(H$41=0,$C$6*$C$7=0),0,($C48/(Assumptions!$F$20*H$41))/($C$6*$C$7)) -> 19.188667 | I48: =IF(OR(I$41=0,$C$6*$C$7=0),0,($C48/(Assumptions!$F$20*I$41))/($C$6*$C$7)) -> 17.132738 | J48: =IF(OR(J$41=0,$C$6*$C$7=0),0,($C48/(Assumptions!$F$20*J$41))/($C$6*$C$7)) -> 14.991146

Sheet Dashboard
B2: DASHBOARD
B3: Headline outputs on the live scenario. Change Assumptions!B5 to switch case.
B5: Active scenario | C5: =Assumptions!B6 -> Base
B7: SCALE AT MONTH 36
